File: Mixtures/xrdml/NIST Rutile (80%) with NIST Corundum (20%).XRDML
<?xml version="1.0" encoding="UTF-8"?>
<xrdMeasurements xmlns="http://www.xrdml.com/XRDMeasurement/1.3" xmlns:xsi="http://www.w3.org/2001/XMLSchema-instance" xsi:schemaLocation="http://www.xrdml.com/XRDMeasurement/1.3 http://www.xrdml.com/XRDMeasurement/1.3/XRDMeasurement.xsd" status="Completed">
	<comment>
		<entry>Configuration=Spinner Stage, Owner=User-1, Creation date=12/11/2006 3:54:51 PM</entry>
		<entry>Goniometer=PW3050/60 (Theta/Theta); Minimum step size 2Theta:0.001; Minimum step size Omega:0.001</entry>
		<entry>Sample stage=Spinner PW3064</entry>
		<entry>Diffractometer system=XPERT-PRO</entry>
		<entry>Measurement program=Rutile with ISTD, Owner=User-1, Creation date=1/19/2010 2:58:36 PM</entry>
		<entry>Rutile (NIST 674) &amp; ISTD Corundum (NIST 676a)</entry>
	</comment>
	<sample type="To be analyzed">
		<id>Rutile 20A RR (S-2010-001053)</id>
		<name>80.0 % Rutile NIST 674 + 20.0 % Corundum (ISTD) NIST 676a</name>
		<preparedBy>Ashraf Z Khan</preparedBy>
	</sample>
	<xrdMeasurement measurementType="Scan" status="Completed">
		<usedWavelength intended="K-Alpha 1">
			<kAlpha1 unit="Angstrom">1.540598</kAlpha1>
			<kAlpha2 unit="Angstrom">1.544426</kAlpha2>
			<kBeta unit="Angstrom">1.392250</kBeta>
			<ratioKAlpha2KAlpha1>0.500000</ratioKAlpha2KAlpha1>
		</usedWavelength>
		<incidentBeamPath>
			<radius unit="mm">240.000</radius>
			<xRayTube>
				<tension unit="kV">45</tension>
				<current unit="mA">40</current>
				<anodeMaterial>Cu</anodeMaterial>
			</xRayTube>
			<divergenceSlit xsi:type="fixedDivergenceSlitType">
				<angle unit="deg">0.250</angle>
			</divergenceSlit>
		</incidentBeamPath>
		<diffractedBeamPath>
			<radius unit="mm">240.000</radius>
			<receivingSlit>
				<height unit="mm">0.100</height>
			</receivingSlit>
		</diffractedBeamPath>
		<scan appendNumber="0" mode="Continuous" scanAxis="Gonio" status="Completed">
			<header>
				<startTimeStamp>2010-03-23T10:43:53</startTimeStamp>
				<author>
					<name>mplabs</name>
				</author>
				<source>
					<applicationSoftware version="2.2.5">X'Pert HighScore Plus</applicationSoftware>
				</source>
			</header>
			<dataPoints>
				<positions axis="2Theta" unit="deg">
					<startPosition>20.002</startPosition>
					<endPosition>89.968</endPosition>
				</positions>
				<commonCountingTime unit="seconds">657.390</commonCountingTime>
				<intensities unit="counts">6651 6594 6837 6775 6751 6619 6821 6733 6519 6594 6538 6642 6563 6597 6668 6420 6505 6444 6494 6421 6497 6326 6390 6459 6351 6338 6310 6376 6288 6352 6315 6316 6299 6291 6293 6162 6115 6275 6248 6263 6251 6201 6257 6220 6144 6154 6103 6205 6257 6199 6067 6016 6072 5975 5969 6042 5980 5970 6085 6010 5989 6075 6029 5972 5899 5892 5953 5954 5978 5947 5872 5848 5788 5718 5938 5892 5749 5690 5929 5748 5748 5777 5826 5699 5750 5803 5669 5664 5621 5638 5679 5554 5582 5534 5576 5485 5678 5599 5598 5463 5552 5538 5612 5527 5624 5571 5468 5533 5571 5527 5380 5342 5355 5230 5320 5221 5168 5252 5298 5247 5270 5205 5279 5321 5227 5200 5272 5261 5123 5206 5252 5142 5180 5229 5273 5242 5188 5083 5091 5103 5032 5077 5061 5024 5125 5100 5059 5064 5002 5001 5083 5144 5156 5084 5004 5029 5053 4974 4863 4807 4831 4930 4902 4808 4865 4951 4995 4931 4874 4848 4858 4825 4890 4885 4850 4879 4887 4892 4886 4823 4855 4962 5000 5106 5074 5023 4928 4885 4799 4804 4754 4680 4846 4692 4689 4712 4744 4840 4859 4757 4990 5032 5141 5292 5553 6020 5983 5836 5722 5652 5560 5640 5939 6413 7211 8546 9620 8529 7548 6810 5684 5047 4783 4747 4610 4528 4437 4501 4573 4563 4532 4548 4404 4432 4350 4312 4377 4429 4410 4434 4445 4381 4414 4421 4344 4442 4494 4453 4502 4563 4574 4639 4753 4820 4859 4776 4717 4793 4765 4699 4696 4707 4686 4682 4776 4874 4913 4940 4920 4917 4956 5070 5224 5344 5649 6046 6490 7224 8207 9520 11205 14175 18434 24669 34389 49728 73861 100555 104447 80295 63182 47038 25561 14811 11052 9100 7818 6859 6354 5653 5355 5211 4917 4946 4784 4565 4543 4471 4282 4427 4401 4426 4289 4389 4281 4261 4133 4103 4098 4052 4111 4082 4079 4133 3982 4012 3977 4014 3984 3872 3881 3858 3866 3856 3879 3836 3798 3849 3847 3823 3793 3828 3838 3717 3753 3805 3780 3707 3728 3778 3788 3772 3723 3733 3700 3714 3722 3600 3620 3659 3654 3691 3621 3599 3646 3599 3549 3557 3592 3564 3544 3538 3538 3583 3561 3561 3499 3533 3554 3544 3573 3538 3511 3548 3557 3563 3462 3448 3369 3465 3433 3303 3407 3409 3467 3402 3419 3436 3372 3420 3394 3379 3388 3356 3329 3280 3370 3331 3299 3163 3194 3284 3287 3242 3324 3251 3216 3223 3220 3229 3271 3186 3177 3218 3196 3261 3177 3067 3163 3242 3257 3149 3070 3131 3147 3175 3220 3172 3146 3137 3127 3178 3174 3065 3076 3156 3163 3142 3027 3005 3045 3029 2977 3015 3059 3026 3040 3013 3005 3059 3049 2972 2919 2953 2965 2929 2936 2978 3026 3001 2992 2933 2887 2911 2916 2881 2858 2892 2951 2993 2940 2938 2940 2967 2943 2825 2840 2861 3001 2926 2912 2898 2915 2934 2863 2809 2805 2721 2778 2732 2764 2744 2805 2829 2673 2782 2775 2737 2696 2720 2766 2721 2758 2774 2808 2695 2663 2641 2702 2694 2667 2702 2810 2767 2682 2707 2668 2656 2699 2680 2654 2677 2723 2634 2623 2704 2682 2685 2716 2655 2660 2715 2763 2715 2717 2650 2625 2649 2583 2574 2665 2664 2600 2598 2660 2732 2658 2568 2598 2588 2624 2665 2619 2548 2484 2582 2609 2630 2655 2642 2746 2813 2782 2853 3026 2981 3043 3258 3400 3657 4124 4910 6148 8071 9771 8956 6757 6574 6291 4684 3632 3193 3012 2985 2905 2868 2882 2821 2883 2849 2773 2804 2947 2774 2921 2994 3103 3076 3347 3708 3845 4236 4656 5552 6699 8707 11961 17496 27193 40351 46029 35876 27405 26673 22286 13766 8176 5836 4832 4135 3752 3483 3235 3059 2976 2841 2801 2750 2695 2638 2547 2559 2597 2591 2518 2536 2504 2501 2468 2430 2480 2444 2449 2471 2447 2451 2479 2438 2379 2421 2407 2373 2371 2330 2334 2372 2362 2302 2259 2298 2289 2343 2354 2332 2374 2358 2412 2453 2452 2539 2683 2919 3356 3912 4813 5593 4962 4107 4084 4057 3379 2860 2656 2624 2425 2287 2349 2384 2380 2207 2153 2234 2233 2257 2294 2193 2259 2120 2257 2234 2132 2169 2167 2172 2258 2322 2212 2200 2246 2193 2235 2155 2193 2197 2177 2250 2152 2139 2163 2284 2306 2458 2560 2641 2746 3092 3661 4608 5991 7431 7378 6114 5394 5184 4674 3659 2900 2558 2432 2322 2236 2212 2192 2206 2183 2101 2053 2130 2186 2104 2036 2079 2136 2120 2110 2080 2098 2094 2037 2066 2051 2041 2063 2076 2051 2052 2025 1988 2019 2072 2107 2091 1979 2050 2115 1980 2002 2009 1984 1948 1928 2042 2005 2036 2018 2045 2032 1954 2033 2054 2055 2058 2101 2051 2153 2247 2212 2450 2412 2694 2882 3064 3491 4047 5400 7580 11392 17418 22645 20080 14040 12335 13208 11421 7374 4669 3481 3060 2725 2540 2412 2309 2290 2144 2145 2150 2123 2045 2040 2053 1999 2006 1977 1952 1887 1925 1956 1922 1904 1900 1920 1913 1901 1878 1824 1816 1810 1805 1839 1886 1877 1852 1862 1827 1828 1851 1880 1915 1908 1901 1869 1808 1795 1845 1900 1891 1842 1800 1832 1834 1805 1863 1857 1898 1896 1851 1857 1883 1976 2055 2138 2162 2344 2448 2618 3078 3617 4794 6680 9063 9564 6600 5310 5653 6031 4754 3160 2670 2347 2148 2117 2122 1963 2029 2038 2027 2083 2093 2203 2223 2439 2659 3160 3954 5423 7601 8755 7542 5762 5222 5426 5055 3854 2898 2359 2131 1987 1970 1834 1821 1832 1778 1759 1748 1685 1709 1742 1756 1749 1722 1692 1701 1721 1685 1656 1660 1634 1647 1674 1638 1624 1619 1642 1690 1691 1670 1629 1624 1603 1564 1546 1552 1559 1634 1599 1549 1502 1525 1568 1596 1585 1577 1559 1541 1547 1617 1520 1534 1616 1566 1601 1638 1530 1518 1587 1585 1562 1513 1569 1510 1493 1505 1558 1503 1548 1525 1581 1545 1670 1606 1604 1523 1484 1565 1603 1536 1511 1624 1487 1569 1517 1457 1467 1442 1495 1474 1443 1509 1490 1427 1403 1473 1470 1440 1434 1486 1499 1467 1485 1448 1440 1466 1459 1441 1410 1467 1468 1488 1534 1494 1463 1466 1497 1449 1444 1490 1501 1486 1463 1444 1421 1451 1498 1508 1469 1432 1451 1456 1449 1441 1446 1473 1496 1515 1501 1522 1583 1623 1662 1710 1743 1700 1635 1637 1633 1566 1553 1484 1488 1456 1399 1395 1332 1379 1369 1360 1376 1461 1428 1447 1431 1462 1456 1442 1471 1485 1472 1548 1495 1459 1411 1432 1383 1419 1415 1351 1386 1326 1412 1382 1447 1395 1355 1289 1350 1335 1361 1352 1316 1349 1419 1381 1348 1373 1398 1354 1331 1404 1393 1371 1339 1359 1408 1376 1346 1323 1347 1352 1347 1371 1388 1393 1363 1356 1399 1381 1334 1329 1349 1334 1299 1307 1361 1384 1336 1257 1248 1288 1272 1297 1300 1319 1286 1287 1307 1320 1327 1343 1350 1372 1328 1323 1330 1418 1336 1381 1374 1306 1307 1367 1369 1326 1309 1355 1365 1282 1268 1301 1309 1311 1267 1299 1271 1265 1288 1339 1278 1287 1343 1242 1334 1330 1362 1302 1310 1336 1287 1321 1276 1314 1268 1320 1296 1258 1284 1318 1286 1313 1324 1266 1299 1334 1257 1267 1277 1285 1278 1344 1328 1306 1352 1392 1469 1473 1555 1660 1692 1761 1891 2112 2408 2964 3892 4684 4271 3133 2679 2845 3071 3021 2497 1989 1751 1613 1587 1590 1573 1530 1465 1476 1494 1441 1442 1407 1381 1369 1380 1371 1386 1423 1421 1442 1412 1427 1417 1438 1440 1436 1489 1448 1394 1451 1464 1453 1501 1534 1506 1501 1624 1581 1612 1638 1771 1772 2011 2001 2069 2138 2252 2465 2867 3232 3579 3882 4343 5365 6869 9941 15502 25634 41194 53761 47187 30145 21291 21754 27060 28590 21335 12740 7684 5353 4118 3417 3033 2711 2457 2206 2090 1937 1862 1797 1730 1682 1701 1684 1651 1647 1668 1708 1696 1652 1605 1529 1520 1551 1529 1507 1456 1440 1491 1491 1469 1444 1375 1323 1339 1355 1345 1345 1377 1362 1328 1364 1326 1320 1323 1384 1338 1355 1378 1325 1304 1349 1363 1374 1360 1357 1388 1401 1454 1382 1435 1418 1462 1499 1513 1529 1686 1733 1875 1993 2077 2218 2555 3167 4126 6138 9818 14808 17110 12972 8196 6512 7059 8709 9371 7090 4432 3020 2367 2077 1878 1736 1652 1585 1621 1560 1485 1483 1427 1584 1531 1586 1667 1676 1723 1834 2046 2367 2883 3797 5562 7400 7254 5359 3860 3511 3910 4530 4407 3356 2352 1924 1736 1590 1501 1420 1354 1340 1359 1351 1274 1237 1251 1248 1216 1174 1216 1247 1211 1184 1189 1172 1150 1140 1158 1157 1147 1138 1139 1163 1153 1118 1160 1147 1105 1147 1143 1148 1168 1130 1148 1106 1105 1081 1095 1121 1086 1115 1163 1128 1105 1063 1143 1132 1144 1070 1145 1128 1113 1084 1084 1054 1075 1092 1148 1164 1111 1110 1092 1144 1098 1177 1083 1108 1147 1189 1229 1286 1240 1232 1206 1173 1182 1221 1262 1221 1103 1114 1174 1143 1148 1124 1084 1052 1046 1095 1110 1080 1080 1073 1073 1070 1088 1085 1060 1061 1075 1060 1081 1105 1082 1099 1097 1076 1081 1109 1115 1075 1058 1042 1082 1102 1116 1092 1073 1094 1094 1138 1171 1207 1290 1320 1312 1240 1237 1306 1492 1638 1631 1486 1270 1234 1271 1306 1371 1336 1264 1169 1129 1133 1083 1116 1060 1060 1084 1071 1094 1070 1117 1089 1106 1091 1019 1028 1095 1094 1050 1093 1125 1154 1069 1080 1123 1094 1154 1117 1135 1132 1144 1158 1174 1185 1255 1320 1340 1403 1385 1547 1712 2074 2725 3900 5680 7811 7987 6030 4014 3235 3358 4042 4736 4391 3208 2239 1667 1386 1329 1275 1215 1177 1124 1104 1115 1138 1123 1099 1084 1053 1075 1097 1093 1083 1109 1060 1060 1102 1105 1076 1103 1168 1164 1196 1259 1292 1279 1341 1402 1548 1805 2223 2953 4232 6167 7580 6905 4954 3564 3083 3279 3987 4377 3915 2833 2055 1697 1435 1272 1199 1215 1112 1106 1066 1068 1041 1050 1049 1076 1027 973 967 1047 976 974 979 973 973 1008 1033 1002 1001 982 966 993 986 994 986 965 931 954 1029 1049 937 1017 1030 991 1041 1125 1168 1319 1456 1445 1314 1207 1164 1143 1190 1248 1213 1159 1068 1000 1010 1000 971 979 988 956 939 946 949 959 983 981 1018 1063 1070 1067 1056 1077 1125 1168 1152 1169 1329 1495 1707 2190 2828 3326 3107 2325 1828 1658 1751 1956 2202 2146 1743 1406 1222 1133 1140 1095 1087 1057 990 983 984 945 1012 1017 988 955 1032 1054 1013 986 952 970 996 898 943 962 1005 966 1019 969 1015 1031 978 1013 1001 1008 1027 1026 967 1057 1055 1036 1066 1070 1107 1146 1173 1231 1240 1280 1347 1441 1716 2131 2673 3735 4611 4236 3143 2328 2018 2062 2381 2799 2879 2454 1857 1544 1479 1410 1392 1378 1359 1440 1537 1593 1652 1749 1875 2088 2321 2729 3521 4826 7159 11026 15403 16875 13603 8874 6194 5502 6189 7951 9480 8755 6376 4140 2841 2280 1873 1693 1600 1604 1558 1492 1411 1450 1392 1552 1585 1624 1898 2404 3128 4481 7109 9348 9257 6307 4134 3176 3050 3634 4821 5469 4631 3232 2241 1700 1492 1302 1248 1149 1189 1172 1193 1063 1042 1085 1066 1097 1062 1021 1024 1016 985 988 1004 1024 1019 984 936 946 948 896 885 902 859 840 856 868 898 879 900 942 901 891 902 867 849 881 897 886 866 844 856 866 870 850 861 847 823 830 866 861 840 830 849 879 882 866 862 883 885 863 862 856 807 806 832 787 835 888 820 846 891 852 898 844 845 920 871 878 995 1133 1336 1582 1651 1652 1388 1190 1031 1042 1111 1270 1268 1254 1097 996 943 918 899 852 824 795 813 800 786 793 812 845 849 812 769 825 821 802 814 849 826 826 823 802 802 789 820 827 793 807 812 790 792 812 809 804 801 825 831 788 788 799 807 810 795 822 813 790 819 808 780 783 826 873 859 836 834 819 868 878 883 933 924 962 1026 995 956 856 829 867 874 885 915 893 888 810 750 799 823 772 732 806 770 793 872 778 789 848 895 847 852 840 808 877 820 857 833 821 847 826 784 775 809 734 788 751 749 745 766 778 777 758 780 773 735 764 765 792 769 775 791 791 818 814 798 763 771 804 809 801 801 852 838 785 801 849 907 914 898 916 931 982 1088 1275 1588 2040 2497 2476 1978 1525 1284 1237 1323 1493 1736 1871 1794 1684 1729 1928 1883 1595 1334 1138 1076 1081 1143 1278 1367 1356 1218 1286 1278 1407 1316 1165 1091 950 872 877 890 1006 1002 1012 925 864 867 833 771 824 808 766 762 805 765 793 727 704 725 798 775 745 749 786 762 752 709 750 682 692 731 737 721 756 740 721 709 716 724 695 686 717 752 752 745 763 755 716 732 757 726 717 726 777 759 700 739 775 751 758 759 721 714 748 760 732 742 747 719 717 714 722 748 727 734 764 738 725 758 759 757 752 775 801 738 776 823 810 855 945 1040 1241 1540 1649 1510 1222 1037 933 915 914 1016 1012 1222 1103 1039 894 847 842 787 758 726 786 694 728 808 776 798 752 751 771 803 822 817 874 926 1008 1154 1109 964 882 841 838 820 789 830 944 878 830 828 808 814 780 730 718 743 750 760 765 764 730 745 761 745 741 739 743 737 722 701 697 733 766 735 704 735 752 739 727 730 743 776 779 790 788 752 817 817 796 820 860 858 887 966 1093 1164 1320 1666 2300 3088 3870 3832 3086 2154 1598 1382 1376 1512 1771 2166 2403 2124 1681 1401 1118 1028 914 874 875 823 873 746 794 812 787 817 807 817 773 749 733 791 762 760 777 738 734 741 731 754 785 806 748 712 739 743 716 718 719 696 714 750 762 731 731 766 778 767 744 751 750 759 787 804 834 852 900 916 967 1060 1226 1560 1994 2475 2752 2544 2078 1714 1500 1371 1339 1406 1562 1776 1778 1639 1426 1177 1053 1026 927 833 794 756 799 804 801 812 746 717 741 740 699 695 717 697 731 711 709 744 716 679 671 666 678 797 688 722 707 707 683 690 668 714 683 662 691 672 722 722 765 719 705 716 746 712 677 681 651 734 718 654 702 699 720 717 756 744 712 713 741 766 786 905 925 914 881 860 829 837 870 895 858 832 817 828 855 830 768 799 838 781 742 757 746 722 711 698 704 729 737 723 733 731 719 716 723 742 721 741 739 721 758 796 876 952 1059 1280 1386 1296 1197 1034 905 844 819 815 925 972 1017 1015 995 866 789 800 777 744 757 789 667 697 681 723 668 709 709 684 699 706 692 657 686 684 659 682 693 704 672 725 681 702 712 706 676 665 687 725 723 764 776 800 781 781 834 885 979 1013 1094 1113 1059 954 882 899 894 912 918 935 996 1072 1149 1160 1196 1229 1367 1658 2144 2946 4162 5553 5972 4999 3555 2425 1850 1688 1660 1826 2144 2710 3266 3262 2735 2066 1530 1264</intensities>
			</dataPoints>
			<nonAmbientPoints type="Temperature" unit="K">
				<measurementTimes unit="seconds" deltaTime="1">0</measurementTimes>
				<nonAmbientValues>298.000</nonAmbientValues>
			</nonAmbientPoints>
		</scan>
	</xrdMeasurement>
</xrdMeasurements>