File: Mixtures/xrdml/NIST RUtle (50%) with NIST Corudnum (50%).XRDML
<?xml version="1.0" encoding="UTF-8"?>
<xrdMeasurements xmlns="http://www.xrdml.com/XRDMeasurement/1.3" xmlns:xsi="http://www.w3.org/2001/XMLSchema-instance" xsi:schemaLocation="http://www.xrdml.com/XRDMeasurement/1.3 http://www.xrdml.com/XRDMeasurement/1.3/XRDMeasurement.xsd" status="Completed">
	<comment>
		<entry>Configuration=Spinner Stage, Owner=User-1, Creation date=12/11/2006 3:54:51 PM</entry>
		<entry>Goniometer=PW3050/60 (Theta/Theta); Minimum step size 2Theta:0.001; Minimum step size Omega:0.001</entry>
		<entry>Sample stage=Spinner PW3064</entry>
		<entry>Diffractometer system=XPERT-PRO</entry>
		<entry>Measurement program=Rutile with ISTD, Owner=User-1, Creation date=1/19/2010 2:58:36 PM</entry>
		<entry>Rutile (NIST 674) &amp; ISTD Corundum (NIST 676a)</entry>
	</comment>
	<sample type="To be analyzed">
		<id>Rutile 50A RR (S-2010-001054)</id>
		<name>50.0 % Rutile NIST 674 + 50.0 % Corundum (ISTD) NIST 676a</name>
		<preparedBy>Ashraf Z Khan</preparedBy>
	</sample>
	<xrdMeasurement measurementType="Scan" status="Completed">
		<usedWavelength intended="K-Alpha 1">
			<kAlpha1 unit="Angstrom">1.540598</kAlpha1>
			<kAlpha2 unit="Angstrom">1.544426</kAlpha2>
			<kBeta unit="Angstrom">1.392250</kBeta>
			<ratioKAlpha2KAlpha1>0.500000</ratioKAlpha2KAlpha1>
		</usedWavelength>
		<incidentBeamPath>
			<radius unit="mm">240.000</radius>
			<xRayTube>
				<tension unit="kV">45</tension>
				<current unit="mA">40</current>
				<anodeMaterial>Cu</anodeMaterial>
			</xRayTube>
			<divergenceSlit xsi:type="fixedDivergenceSlitType">
				<angle unit="deg">0.250</angle>
			</divergenceSlit>
		</incidentBeamPath>
		<diffractedBeamPath>
			<radius unit="mm">240.000</radius>
			<receivingSlit>
				<height unit="mm">0.100</height>
			</receivingSlit>
		</diffractedBeamPath>
		<scan appendNumber="0" mode="Continuous" scanAxis="Gonio" status="Completed">
			<header>
				<startTimeStamp>2010-03-23T10:46:31</startTimeStamp>
				<author>
					<name>mplabs</name>
				</author>
				<source>
					<applicationSoftware version="2.2.5">X'Pert HighScore Plus</applicationSoftware>
				</source>
			</header>
			<dataPoints>
				<positions axis="2Theta" unit="deg">
					<startPosition>20.002</startPosition>
					<endPosition>89.968</endPosition>
				</positions>
				<commonCountingTime unit="seconds">657.390</commonCountingTime>
				<intensities unit="counts">7177 7275 7370 7405 7336 7290 7171 7198 7126 7197 7065 7143 7044 7192 7050 7032 7191 7029 6998 6932 7044 7112 6975 7007 7046 6969 6964 6976 6946 6998 6943 6780 6766 6814 6826 6818 6848 6796 6755 6761 6713 6691 6727 6735 6760 6687 6647 6683 6688 6597 6528 6665 6629 6514 6543 6522 6530 6555 6566 6514 6522 6547 6489 6364 6350 6446 6495 6448 6387 6390 6457 6423 6350 6327 6259 6287 6288 6278 6259 6407 6361 6372 6332 6282 6365 6086 6184 6072 6179 6232 6087 6176 6175 6063 5938 6135 6106 6044 6072 6079 5997 6145 5969 5916 6047 6017 5849 6089 6101 5910 5927 5887 5851 5976 5899 5912 5840 5793 5921 5836 5809 5946 5843 5789 5853 5740 5719 5861 5754 5747 5764 5718 5801 5774 5712 5714 5656 5659 5661 5708 5683 5630 5553 5587 5592 5589 5635 5579 5559 5579 5554 5457 5427 5512 5502 5578 5570 5415 5443 5434 5436 5436 5423 5415 5367 5364 5442 5518 5477 5354 5443 5449 5345 5246 5250 5363 5393 5374 5373 5417 5473 5539 5500 5572 5571 5534 5511 5343 5371 5358 5311 5295 5338 5335 5331 5253 5432 5361 5386 5506 5487 5768 5812 6033 6396 6703 6884 7127 6969 7239 7660 8517 9939 11926 15275 19844 21996 17749 15188 12183 8833 6980 6301 5857 5675 5504 5259 5304 5125 5023 5092 4963 4993 5090 4929 4898 4976 4962 5036 4989 4960 4888 4932 4992 4922 4938 4950 4895 4959 5022 5106 5230 5284 5252 5169 5138 5137 5119 5152 5200 5205 5247 5273 5269 5289 5374 5346 5395 5444 5415 5459 5458 5579 5773 6083 6440 6912 7585 8517 9874 11691 14552 18538 24710 34301 49047 71182 91618 88254 67812 54748 38789 21650 13949 10551 9100 7989 7061 6553 6110 5906 5704 5456 5418 5209 5182 5036 4936 4934 4927 4824 4802 4865 4792 4780 4699 4576 4643 4768 4639 4488 4640 4464 4448 4543 4540 4483 4471 4430 4418 4338 4270 4347 4306 4271 4408 4297 4335 4329 4296 4323 4285 4225 4226 4239 4204 4249 4226 4119 4165 4195 4175 4215 4204 4157 4166 4090 4017 4073 4022 3971 4037 4060 4033 4029 3991 3994 3988 4008 4048 4046 3975 3973 3919 3890 3882 3910 3907 3904 3929 3947 3906 3953 4019 4005 3918 4015 4067 3978 3957 3832 3790 3774 3881 3717 3709 3936 3794 3895 3975 3763 3882 3831 3804 3798 3680 3851 3738 3742 3688 3730 3726 3608 3712 3719 3757 3643 3677 3755 3632 3614 3675 3638 3713 3654 3683 3697 3615 3545 3565 3527 3510 3566 3640 3652 3660 3629 3607 3639 3661 3723 3779 3757 3711 3688 3762 3736 3647 3612 3595 3606 3586 3491 3477 3491 3419 3416 3439 3425 3428 3432 3469 3447 3386 3357 3363 3429 3374 3346 3339 3358 3360 3373 3368 3361 3426 3357 3403 3359 3385 3332 3382 3381 3358 3273 3289 3315 3262 3395 3271 3272 3234 3333 3169 3248 3262 3173 3290 3187 3222 3156 3272 3221 3263 3291 3196 3049 3234 3122 3055 3048 3125 3152 3159 3092 3103 3137 3198 3169 3124 3100 3065 3124 3125 3079 3091 3106 3120 3096 3082 3057 3052 3057 3126 3131 3179 3131 3212 3214 3169 3175 3200 3190 3114 3051 3101 3164 3195 3166 3068 2996 3012 3108 3180 3131 3086 3154 3143 3054 3036 3072 3172 3215 3160 3155 3211 3216 3267 3301 3288 3472 3642 3711 3815 3922 4191 4655 5058 5761 6767 8520 11581 16360 23310 27853 22939 16786 16493 14943 9340 6272 5261 4494 4176 3999 3842 3703 3643 3590 3552 3697 3660 3667 3499 3630 3734 3741 3824 4062 4144 4399 4645 5269 6029 7221 9239 12234 17816 26900 37851 39232 29942 24604 23676 18711 11808 7690 5977 5001 4352 4091 3772 3544 3430 3389 3344 3205 3150 3148 3052 3043 2982 2933 2971 2950 2953 2972 2963 2960 2922 2921 2949 2980 2900 2857 2816 2768 2823 2824 2812 2849 2858 2832 2784 2720 2773 2788 2778 2787 2778 2758 2804 2887 2949 2925 3028 3211 3255 3527 3817 4309 5066 6452 8447 11393 13358 11028 8329 8432 8207 5967 4333 3718 3412 3283 2966 2848 2833 2766 2699 2696 2699 2641 2630 2536 2544 2649 2534 2572 2588 2641 2619 2642 2580 2631 2570 2546 2460 2522 2495 2571 2483 2516 2592 2475 2558 2503 2527 2631 2710 2750 2795 2857 2947 3095 3359 3888 4800 6095 7062 6783 5763 5323 5067 4476 3752 3180 2805 2661 2611 2600 2568 2557 2541 2487 2456 2463 2445 2392 2398 2409 2425 2445 2423 2432 2420 2339 2354 2439 2396 2359 2339 2399 2460 2431 2356 2379 2344 2388 2390 2359 2340 2341 2357 2270 2404 2440 2403 2340 2272 2313 2231 2215 2277 2400 2310 2449 2350 2391 2357 2366 2412 2399 2435 2473 2532 2496 2659 2890 2920 3141 3529 3684 4285 5559 7765 11333 16498 19880 16509 12044 11283 11829 9573 6297 4432 3620 3122 2915 2795 2670 2653 2555 2563 2595 2571 2507 2426 2460 2483 2486 2405 2322 2326 2379 2351 2277 2241 2263 2311 2325 2278 2218 2254 2270 2242 2247 2231 2237 2277 2271 2242 2243 2244 2242 2215 2203 2275 2247 2169 2242 2276 2303 2280 2280 2273 2343 2365 2296 2326 2361 2359 2409 2428 2574 2590 2620 2753 2896 3083 3227 3712 4179 4586 5380 6722 9329 13736 20360 28146 26837 17657 14350 15814 16088 10747 6435 4695 4141 3618 3303 2967 2905 2673 2756 2657 2612 2647 2613 2739 2869 3162 3542 4342 5656 7202 7823 6593 5308 5073 5257 4719 3762 2949 2628 2416 2316 2225 2153 2156 2117 2071 2076 1992 2011 2068 2090 2028 2025 2028 1985 1964 1977 1957 1972 1985 1919 1900 1943 1977 1961 1909 1874 1894 1952 1922 1924 1997 1936 1867 1877 1871 1878 1855 1845 1853 1876 1905 1906 1896 1863 1849 1839 1859 1847 1831 1840 1802 1833 1853 1862 1880 1905 1851 1880 1910 1868 1863 1845 1844 1873 1878 1860 1823 1932 1936 1980 2081 2119 2020 1948 1945 2037 2042 1944 1860 1811 1804 1812 1747 1804 1786 1795 1772 1806 1796 1773 1740 1732 1796 1843 1783 1730 1790 1794 1732 1738 1704 1732 1758 1714 1737 1729 1777 1813 1825 1789 1776 1794 1796 1726 1687 1674 1697 1730 1770 1767 1709 1708 1716 1740 1743 1724 1764 1757 1731 1727 1714 1722 1738 1721 1732 1800 1781 1787 1769 1826 1930 1996 2005 1995 2003 1969 1951 1922 2033 1932 1897 1908 1902 1857 1857 1841 1889 1798 1776 1797 1881 1748 1659 1705 1761 1741 1761 1743 1801 1846 1798 1735 1745 1576 1624 1641 1660 1623 1672 1578 1609 1594 1628 1573 1575 1547 1586 1607 1636 1620 1627 1631 1680 1682 1649 1622 1685 1604 1619 1623 1544 1570 1610 1599 1665 1628 1636 1616 1604 1572 1593 1621 1609 1636 1626 1571 1581 1603 1564 1579 1568 1524 1546 1586 1584 1555 1555 1556 1544 1567 1620 1559 1491 1544 1540 1551 1555 1542 1601 1579 1534 1541 1588 1647 1587 1611 1610 1582 1602 1597 1605 1545 1584 1599 1625 1586 1532 1575 1535 1567 1615 1568 1568 1518 1595 1588 1638 1572 1479 1514 1601 1546 1587 1548 1618 1629 1576 1656 1529 1555 1635 1593 1588 1592 1593 1657 1602 1516 1542 1620 1627 1533 1502 1575 1681 1704 1635 1681 1704 1656 1643 1715 1800 1799 1976 2106 2124 2256 2441 2635 2894 3314 4016 5315 7551 10734 12506 10479 7423 6224 6631 7529 6996 5089 3640 2934 2588 2322 2124 2101 1994 1930 1921 1845 1779 1767 1732 1739 1785 1735 1654 1658 1714 1689 1663 1692 1695 1694 1637 1694 1683 1674 1660 1718 1752 1706 1691 1764 1770 1771 1739 1806 1865 1864 1963 1980 2048 2148 2149 2356 2357 2567 2773 3033 3304 3672 4036 4375 5559 7342 9992 15756 24499 37015 44340 36377 24023 18459 19997 23580 23183 16504 10164 6581 4938 4094 3461 3087 2794 2584 2392 2268 2170 2069 2069 1992 1926 1878 1851 1918 1872 1880 1889 1886 1879 1805 1749 1736 1740 1743 1693 1674 1650 1630 1705 1713 1658 1649 1620 1614 1638 1657 1649 1618 1638 1609 1579 1574 1633 1623 1584 1591 1591 1572 1614 1627 1549 1577 1613 1574 1582 1602 1619 1716 1668 1725 1743 1715 1707 1859 1889 1961 2086 2055 2239 2320 2471 2920 3410 4535 6471 9513 13463 14077 10435 7119 6214 7030 8252 8190 6042 4086 3029 2624 2264 2158 2101 2024 1980 2043 2033 2013 2040 2164 2252 2476 2607 2760 2948 3242 3636 4402 5737 8018 11702 17446 22600 20516 14190 10155 9550 11195 13070 11779 8096 5174 3768 3137 2747 2451 2248 2125 2040 1916 1847 1848 1730 1662 1673 1640 1623 1588 1545 1483 1494 1494 1483 1453 1430 1430 1452 1456 1474 1452 1450 1447 1421 1386 1378 1357 1409 1448 1369 1376 1339 1406 1404 1414 1383 1441 1408 1372 1440 1452 1399 1354 1397 1402 1390 1357 1392 1365 1318 1316 1423 1414 1383 1360 1345 1402 1429 1363 1402 1372 1330 1411 1434 1438 1432 1476 1601 1738 1895 1864 1663 1587 1522 1546 1574 1621 1579 1455 1419 1404 1340 1322 1321 1296 1327 1288 1305 1296 1310 1327 1330 1325 1326 1331 1328 1278 1279 1339 1335 1300 1305 1304 1326 1360 1326 1280 1302 1324 1277 1283 1351 1379 1390 1426 1439 1461 1431 1483 1529 1592 1766 2007 2203 2034 1887 1978 2210 2697 3192 3232 2564 2103 1861 1954 2043 2124 2088 1773 1599 1552 1461 1429 1363 1304 1291 1371 1276 1305 1308 1334 1311 1316 1317 1283 1316 1256 1353 1316 1332 1362 1292 1378 1332 1294 1336 1421 1353 1376 1360 1312 1351 1453 1406 1487 1462 1535 1564 1572 1683 1938 2345 2910 3950 5583 7093 6845 5078 3651 3183 3396 3938 4314 3893 2929 2139 1782 1654 1541 1487 1473 1438 1396 1360 1338 1345 1329 1317 1351 1333 1310 1304 1302 1330 1307 1303 1334 1324 1318 1307 1342 1376 1398 1413 1464 1478 1568 1609 1642 1771 2051 2409 3060 4352 5809 6612 5808 4236 3311 2976 3254 3881 4094 3563 2694 2113 1814 1649 1532 1539 1433 1398 1366 1309 1314 1285 1261 1252 1252 1311 1213 1271 1258 1237 1248 1263 1240 1246 1262 1194 1257 1225 1219 1252 1203 1149 1168 1185 1179 1190 1179 1190 1202 1273 1272 1223 1263 1295 1361 1435 1530 1598 1604 1525 1407 1382 1393 1420 1427 1428 1437 1374 1314 1303 1304 1292 1279 1282 1274 1296 1331 1339 1338 1323 1331 1395 1437 1445 1551 1629 1643 1695 1786 1941 2162 2474 3010 3893 5478 7765 9113 7847 5341 3970 3473 3884 4763 5375 4961 3576 2551 2130 1843 1783 1611 1548 1460 1466 1462 1393 1383 1328 1301 1337 1337 1257 1318 1279 1273 1263 1283 1231 1203 1295 1318 1256 1291 1282 1262 1290 1314 1329 1316 1323 1361 1389 1410 1445 1411 1540 1524 1563 1706 1723 1818 1864 1938 2080 2245 2621 3079 3920 5398 7939 11483 13442 11295 7558 5429 4815 5196 6346 7495 7273 5543 3800 2850 2398 2145 2035 1990 1968 1941 1953 1995 1981 2079 2186 2300 2612 3038 3710 5044 7299 10474 13397 13853 10767 7438 5754 5301 5993 7217 8041 7096 5323 3661 2756 2248 2086 1902 1848 1765 1648 1629 1586 1665 1674 1722 1804 1846 2214 2512 3257 4627 6785 8202 7587 5169 3643 2981 3268 3747 4544 4768 3927 2933 2271 1832 1603 1555 1407 1416 1389 1289 1321 1319 1316 1358 1393 1390 1364 1295 1269 1227 1199 1208 1243 1246 1211 1178 1154 1119 1131 1114 1067 1095 1119 1068 1077 1091 1057 1037 1043 1062 1054 1043 1040 1035 1057 1066 1051 1049 1051 1046 1029 1023 1040 1019 1016 1046 1070 1048 1034 1010 1077 1042 1024 1022 1051 1025 1024 1013 1026 980 1024 1024 1027 1023 1029 1017 1006 1052 1059 1048 1046 1063 1034 1088 1052 1098 1031 1144 1162 1273 1435 1712 1825 1600 1454 1274 1225 1180 1274 1343 1396 1264 1234 1126 1062 1053 999 1082 1025 1081 1044 1012 1037 1068 1050 1041 1017 1082 1035 971 1025 1043 1017 1064 1051 1006 1049 1027 992 960 992 1054 1023 997 1018 994 979 1002 989 997 1017 1010 1018 1031 1024 1029 1044 1021 1000 1021 1029 1010 1005 985 979 971 990 1021 1012 1032 1064 1077 1102 1231 1331 1374 1286 1247 1197 1166 1143 1149 1157 1182 1115 1100 1070 1082 1077 1026 1057 1046 978 992 967 944 955 979 995 1002 997 1008 1052 1007 1079 1023 1004 1023 965 952 993 1027 1017 1018 1020 1028 1003 1046 986 1062 990 961 952 953 994 947 998 1000 972 981 970 973 928 960 991 979 962 945 970 1006 992 996 1024 1035 1034 1047 1037 1015 1053 1069 1035 1053 1111 1161 1194 1265 1357 1483 1824 2280 2538 2418 2019 1730 1615 1557 1673 1938 2246 2542 2742 3078 3798 4445 4277 3271 2402 2111 1988 2099 2322 2674 3019 2833 2576 2547 2791 2945 2737 2095 1782 1534 1485 1514 1605 1807 1899 1730 1496 1220 1198 1221 1127 1018 1052 1033 1035 985 1021 1052 981 949 1000 993 1007 943 999 953 964 954 941 963 943 912 947 919 977 921 885 874 922 972 934 947 935 924 932 930 945 920 935 950 962 960 916 912 962 932 901 912 928 906 904 951 933 930 949 951 933 929 955 900 889 908 928 927 925 921 972 978 981 943 917 945 964 953 949 965 963 952 965 1042 1112 1145 1209 1352 1598 1633 1497 1285 1166 1030 1059 1133 1172 1330 1286 1250 1165 1006 973 944 1008 958 981 1001 987 1001 1090 1056 1115 1054 1117 1107 1095 1202 1252 1384 1579 1963 2285 2063 1696 1461 1309 1198 1263 1293 1387 1551 1537 1388 1241 1146 1050 967 935 928 937 912 910 954 947 875 866 883 886 906 921 934 926 938 922 863 885 916 889 885 898 888 907 931 912 926 952 928 929 973 967 959 929 980 1038 1035 1001 1094 1130 1199 1331 1515 1848 2376 3006 3459 3332 2605 1984 1617 1472 1558 1581 1919 2131 2304 2047 1651 1477 1261 1173 1078 1030 1022 975 991 969 989 936 925 905 913 971 975 951 937 947 1007 1035 1083 1115 957 952 943 911 928 951 964 1011 1011 1020 974 963 917 911 904 932 941 927 949 949 945 924 977 986 1007 992 957 1002 1041 1055 1099 1170 1254 1356 1535 1764 2100 2509 2716 2622 2460 2428 2308 2042 1832 1741 1779 1843 1897 1846 1721 1651 1582 1441 1278 1160 1103 1051 982 954 935 948 899 925 868 888 893 904 909 916 933 916 930 906 899 889 910 864 899 975 908 877 938 849 889 848 915 842 857 825 851 883 884 900 886 911 858 847 883 943 928 913 855 909 912 865 871 893 902 954 927 915 971 1013 1052 1136 1234 1431 1608 1668 1565 1408 1387 1411 1446 1463 1386 1360 1359 1339 1275 1215 1142 1132 1171 1189 1154 1072 1016 939 910 920 904 919 920 896 882 888 866 858 856 915 920 957 962 953 966 970 1016 1115 1220 1336 1399 1344 1202 1080 1034 1009 965 1004 1032 1115 1210 1115 1083 1019 954 906 917 865 840 846 839 893 816 872 866 828 896 845 934 865 916 919 889 890 860 861 873 877 850 891 941 886 908 900 926 952 983 951 962 990 1030 1043 1098 1113 1233 1429 1588 1857 2182 2234 1899 1598 1419 1290 1207 1227 1338 1459 1563 1699 1767 1691 1589 1560 1648 1897 2281 2954 3960 4858 4981 4089 2932 2245 1923 1737 1765 1893 2157 2621 2962 2907 2427 1948 1572 1269</intensities>
			</dataPoints>
			<nonAmbientPoints type="Temperature" unit="K">
				<measurementTimes unit="seconds" deltaTime="1">0</measurementTimes>
				<nonAmbientValues>298.000</nonAmbientValues>
			</nonAmbientPoints>
		</scan>
	</xrdMeasurement>
</xrdMeasurements>