File: Mixtures/xrdml/NIST Rutile (90%) with NIST Corundum (10%).XRDML
<?xml version="1.0" encoding="UTF-8"?>
<xrdMeasurements xmlns="http://www.xrdml.com/XRDMeasurement/1.3" xmlns:xsi="http://www.w3.org/2001/XMLSchema-instance" xsi:schemaLocation="http://www.xrdml.com/XRDMeasurement/1.3 http://www.xrdml.com/XRDMeasurement/1.3/XRDMeasurement.xsd" status="Completed">
	<comment>
		<entry>Configuration=Spinner Stage, Owner=User-1, Creation date=12/11/2006 3:54:51 PM</entry>
		<entry>Goniometer=PW3050/60 (Theta/Theta); Minimum step size 2Theta:0.001; Minimum step size Omega:0.001</entry>
		<entry>Sample stage=Spinner PW3064</entry>
		<entry>Diffractometer system=XPERT-PRO</entry>
		<entry>Measurement program=Rutile with ISTD, Owner=User-1, Creation date=1/19/2010 2:58:36 PM</entry>
		<entry>Rutile (NIST 674) &amp; ISTD Corundum (NIST 676a)</entry>
	</comment>
	<sample type="To be analyzed">
		<id>Rutile 10A RR (S-2010-001052)</id>
		<name>90.0 % Rutile NIST 674 + 10.0 % Corundum (ISTD) NIST 676a</name>
		<preparedBy>Ashraf Z Khan</preparedBy>
	</sample>
	<xrdMeasurement measurementType="Scan" status="Completed">
		<usedWavelength intended="K-Alpha 1">
			<kAlpha1 unit="Angstrom">1.540598</kAlpha1>
			<kAlpha2 unit="Angstrom">1.544426</kAlpha2>
			<kBeta unit="Angstrom">1.392250</kBeta>
			<ratioKAlpha2KAlpha1>0.500000</ratioKAlpha2KAlpha1>
		</usedWavelength>
		<incidentBeamPath>
			<radius unit="mm">240.000</radius>
			<xRayTube>
				<tension unit="kV">45</tension>
				<current unit="mA">40</current>
				<anodeMaterial>Cu</anodeMaterial>
			</xRayTube>
			<divergenceSlit xsi:type="fixedDivergenceSlitType">
				<angle unit="deg">0.250</angle>
			</divergenceSlit>
		</incidentBeamPath>
		<diffractedBeamPath>
			<radius unit="mm">240.000</radius>
			<receivingSlit>
				<height unit="mm">0.100</height>
			</receivingSlit>
		</diffractedBeamPath>
		<scan appendNumber="0" mode="Continuous" scanAxis="Gonio" status="Completed">
			<header>
				<startTimeStamp>2010-03-23T10:43:11</startTimeStamp>
				<author>
					<name>mplabs</name>
				</author>
				<source>
					<applicationSoftware version="2.2.5">X'Pert HighScore Plus</applicationSoftware>
				</source>
			</header>
			<dataPoints>
				<positions axis="2Theta" unit="deg">
					<startPosition>20.002</startPosition>
					<endPosition>89.968</endPosition>
				</positions>
				<commonCountingTime unit="seconds">657.390</commonCountingTime>
				<intensities unit="counts">6645 6572 6575 6570 6390 6432 6418 6445 6303 6531 6362 6394 6388 6341 6337 6401 6521 6253 6386 6400 6239 6106 6325 6287 6260 6252 6242 6236 6096 6068 6094 6053 6091 6112 6137 6084 6035 6063 6032 5979 6031 6056 6019 5934 5865 5836 5896 5914 5839 5850 5917 5872 5907 6000 5897 5826 5917 5885 5753 5820 5892 5866 5846 5751 5658 5662 5652 5709 5741 5718 5708 5755 5671 5692 5718 5615 5498 5576 5659 5558 5558 5683 5671 5500 5566 5531 5442 5435 5419 5529 5534 5416 5513 5489 5341 5411 5426 5408 5370 5402 5453 5395 5291 5439 5382 5372 5335 5360 5347 5321 5197 5358 5334 5326 5278 5189 5188 5161 5158 5212 5222 5126 5172 5185 5216 5084 5090 5123 5033 5053 5109 5106 5000 5013 5093 5084 5020 5026 5016 5044 4990 4906 4931 4917 4925 4928 4933 4909 4957 5007 4934 4876 4837 4861 4876 4855 4900 4849 4800 4821 4824 4868 4869 4882 4812 4746 4757 4760 4774 4828 4857 4731 4683 4749 4795 4767 4770 4746 4797 4817 4775 4799 4874 4963 4903 4763 4849 4715 4733 4609 4680 4750 4651 4703 4790 4642 4591 4839 4789 4785 4833 4885 5128 5374 5629 6070 5848 5549 5410 5234 5136 5025 5267 5517 6117 6705 6633 5934 5787 5378 4851 4543 4501 4496 4468 4456 4374 4381 4330 4274 4283 4304 4333 4272 4229 4225 4219 4241 4325 4294 4269 4275 4253 4305 4334 4320 4294 4282 4378 4536 4663 4778 4842 4815 4724 4714 4771 4728 4684 4768 4831 4772 4811 4778 4721 4786 4797 4845 4951 5031 5100 5272 5441 5687 5968 6322 6973 7793 8913 10345 12805 16367 21710 29268 41536 61230 89620 111681 100419 74909 60404 39176 20971 13407 10456 8797 7576 6701 6203 5816 5352 5296 4973 4841 4772 4548 4657 4476 4358 4225 4304 4389 4284 4284 4284 4106 4140 4117 4115 4002 3961 4035 4070 3879 3809 3919 3818 3795 3872 3897 3950 3806 3803 3891 3839 3799 3833 3846 3784 3741 3749 3694 3743 3804 3722 3740 3772 3710 3702 3706 3708 3758 3747 3652 3572 3581 3667 3714 3674 3593 3544 3593 3585 3492 3467 3452 3484 3498 3504 3535 3613 3489 3458 3512 3467 3409 3439 3494 3510 3488 3431 3486 3512 3377 3407 3473 3324 3393 3431 3403 3296 3446 3353 3382 3261 3357 3335 3365 3313 3351 3405 3302 3246 3251 3341 3235 3213 3210 3254 3224 3243 3384 3212 3212 3328 3300 3202 3160 3150 3088 3131 3177 3119 3155 3192 3145 3144 3162 3125 3116 3119 3060 3071 3084 3144 3163 3117 3085 3237 3222 3229 3412 3391 3330 3311 3241 3210 3182 3125 3055 3070 3081 3061 3057 3020 3005 2969 2923 2954 2978 2977 2989 2957 2905 2866 2862 2960 2976 2943 2961 2890 2843 2932 2925 2892 2910 2889 2914 2851 2841 2885 3048 3003 2892 2736 2816 2775 2783 2773 2809 2826 2738 2740 2794 2859 2773 2811 2825 2813 2833 2707 2772 2755 2731 2731 2910 2870 2854 2689 2739 2721 2774 2721 2716 2748 2768 2758 2672 2636 2734 2634 2640 2660 2652 2586 2621 2683 2668 2666 2661 2591 2664 2646 2604 2627 2597 2703 2660 2581 2648 2640 2621 2587 2584 2531 2563 2672 2600 2557 2550 2546 2585 2580 2554 2551 2566 2592 2635 2662 2572 2494 2511 2517 2576 2542 2470 2510 2569 2641 2673 2761 2737 2721 2739 2847 2886 2853 2944 3022 3221 3481 3895 4627 5672 6094 5181 4531 4528 4159 3485 3164 2906 2956 2945 2941 2962 2941 2972 2924 3046 3001 3175 3225 3189 3290 3346 3395 3607 3681 3852 4214 4649 5363 6257 7839 10065 14518 21630 33481 46533 44905 32465 28120 27182 19717 11572 7463 5614 4667 4110 3727 3403 3230 3043 2928 2791 2678 2649 2688 2674 2635 2635 2588 2590 2486 2448 2441 2497 2517 2465 2437 2450 2499 2442 2388 2403 2434 2419 2332 2345 2347 2290 2314 2356 2299 2225 2316 2347 2267 2237 2279 2269 2319 2337 2234 2275 2241 2287 2322 2377 2432 2534 2793 3180 3595 3851 3507 3128 3147 3006 2727 2435 2397 2280 2281 2189 2227 2219 2190 2208 2161 2142 2093 2175 2224 2164 2076 2081 2078 2180 2155 2099 2162 2170 2221 2119 2169 2215 2126 2237 2127 2131 2106 2150 2114 2169 2174 2115 2145 2216 2354 2440 2471 2529 2747 3194 4077 5227 6825 7844 6936 5623 5317 5168 4382 3374 2768 2465 2311 2266 2188 2147 2120 2090 2084 2020 2009 2026 2015 2034 1993 1983 2069 2094 2048 2031 1977 1937 2002 1957 1986 2008 1932 1913 1975 1975 2019 1962 1990 1945 1911 1994 1954 1971 1976 1994 1967 1942 1939 1983 1987 1945 1986 1993 2008 1956 1968 1932 1939 1936 2014 1978 2052 2165 2081 2109 2336 2375 2433 2738 2896 3255 3650 4590 6130 8730 13214 20116 23300 17760 12899 12720 13360 10012 6144 4190 3339 2863 2679 2441 2279 2184 2136 2101 2054 2040 1974 1942 1933 1973 2003 1853 1854 1882 1853 1862 1881 1839 1872 1890 1842 1830 1868 1844 1790 1815 1841 1820 1779 1757 1724 1696 1748 1799 1851 1848 1785 1805 1834 1815 1762 1731 1698 1705 1775 1774 1803 1782 1736 1686 1732 1790 1732 1822 1821 1748 1808 1826 1783 1828 1887 1936 1986 2071 2183 2335 2715 3425 4411 5358 4667 3663 3367 3547 3373 2761 2237 2028 2032 1883 1807 1806 1851 1791 1843 1934 1923 2020 2139 2202 2487 2793 3307 4311 6086 8235 8709 7015 5426 5367 5472 4704 3362 2576 2278 2030 1928 1933 1876 1802 1707 1741 1724 1650 1664 1663 1699 1662 1649 1735 1684 1589 1578 1594 1568 1542 1570 1582 1555 1554 1551 1544 1559 1581 1612 1583 1585 1620 1580 1544 1528 1557 1578 1606 1524 1475 1499 1556 1510 1471 1495 1498 1517 1529 1520 1503 1496 1461 1526 1539 1470 1409 1450 1457 1482 1441 1467 1479 1426 1454 1491 1453 1389 1445 1491 1469 1486 1510 1495 1491 1499 1478 1536 1471 1395 1486 1480 1504 1513 1457 1458 1495 1486 1506 1464 1425 1455 1440 1488 1448 1426 1403 1415 1439 1493 1468 1446 1442 1391 1371 1351 1376 1440 1437 1403 1435 1444 1437 1425 1473 1458 1439 1421 1419 1440 1449 1410 1386 1374 1410 1441 1394 1431 1449 1417 1435 1425 1405 1411 1435 1427 1403 1441 1489 1497 1539 1561 1601 1665 1771 1781 1765 1755 1805 1757 1782 1772 1751 1722 1690 1736 1704 1665 1644 1642 1607 1593 1573 1411 1523 1525 1556 1490 1497 1498 1555 1543 1487 1429 1388 1377 1404 1356 1316 1345 1307 1349 1373 1378 1348 1414 1322 1301 1372 1297 1357 1348 1331 1347 1361 1329 1304 1329 1379 1338 1347 1363 1352 1310 1327 1307 1300 1305 1320 1315 1253 1310 1347 1348 1337 1311 1292 1283 1313 1318 1270 1255 1293 1292 1290 1251 1191 1220 1264 1285 1310 1309 1272 1261 1250 1276 1288 1286 1279 1278 1279 1301 1342 1275 1236 1282 1282 1298 1273 1314 1285 1273 1288 1279 1273 1286 1266 1215 1300 1323 1278 1309 1297 1232 1225 1295 1252 1180 1246 1257 1237 1245 1299 1276 1333 1250 1216 1289 1294 1293 1322 1254 1223 1176 1209 1272 1238 1188 1216 1286 1233 1214 1253 1240 1230 1210 1206 1222 1251 1239 1280 1258 1270 1293 1290 1280 1321 1363 1423 1467 1485 1576 1622 1630 1718 1981 2323 2660 2797 2512 2105 1910 1977 2098 1964 1742 1639 1532 1457 1421 1367 1366 1404 1410 1405 1431 1407 1410 1414 1401 1396 1370 1348 1395 1393 1356 1390 1389 1358 1372 1430 1438 1403 1415 1401 1441 1451 1433 1475 1488 1480 1458 1571 1547 1650 1634 1733 1818 1914 1986 2145 2168 2186 2412 2715 3141 3379 3775 4220 4683 5992 7993 11559 18467 30972 47508 54842 41489 25977 20711 23770 28877 27410 18343 10606 6808 4926 3975 3398 2921 2610 2435 2241 2072 1969 1898 1822 1715 1724 1696 1679 1642 1634 1671 1707 1734 1616 1526 1526 1527 1576 1532 1485 1452 1406 1384 1420 1408 1334 1380 1388 1368 1375 1351 1352 1361 1372 1342 1323 1312 1314 1318 1335 1316 1281 1325 1321 1321 1321 1354 1358 1343 1370 1364 1407 1446 1402 1400 1442 1445 1452 1503 1642 1739 1788 1891 1981 2033 2268 2682 3400 4811 7280 11397 16366 16310 11269 7242 6500 7837 9519 8736 6078 3723 2738 2243 1961 1733 1668 1621 1488 1488 1382 1312 1378 1388 1423 1437 1445 1414 1434 1465 1496 1582 1816 2087 2633 3493 4127 3609 2725 2253 2241 2525 2749 2518 1960 1606 1430 1330 1273 1254 1251 1211 1187 1184 1186 1177 1166 1155 1149 1170 1192 1184 1132 1128 1175 1179 1148 1128 1118 1119 1117 1119 1157 1132 1174 1124 1124 1100 1099 1080 1091 1126 1068 1052 1102 1038 1090 1121 1104 1117 1082 1083 1071 1051 1034 1075 1110 1074 1117 1070 1059 1099 1100 1122 1054 1097 1011 1100 1106 1105 1085 1124 1029 1082 1070 1068 1091 1137 1111 1081 1141 1205 1168 1174 1095 1078 1100 1092 1121 1091 1035 1045 1065 1070 1078 1034 1046 1041 1061 1072 1078 1031 992 1003 1032 1060 1026 1019 1034 1026 1059 1091 1053 1047 1056 1052 1041 1030 1069 1071 1027 1037 1068 1107 1123 1049 1033 1069 1037 1062 1085 1066 1071 1077 1079 1112 1117 1120 1128 1137 1125 1214 1350 1233 1136 1144 1107 1052 1165 1193 1170 1126 1100 1053 1079 1085 1112 1029 1043 1065 1020 1021 1043 1027 1024 1072 1037 1028 1081 1082 1071 1070 1031 1085 1095 1097 1102 1119 1099 1102 1154 1123 1089 1106 1137 1192 1202 1277 1309 1325 1391 1451 1544 1814 2185 3039 4428 6540 8595 7824 5306 3688 3201 3569 4467 4880 4128 2927 2063 1653 1449 1313 1265 1253 1235 1185 1084 1052 1101 1085 1076 1077 1025 1059 1092 1035 1001 1041 1111 1107 1094 1129 1167 1174 1179 1183 1218 1261 1295 1348 1435 1519 1632 1916 2375 3317 4863 6782 7701 6548 4411 3276 3203 3580 4260 4471 3742 2610 1969 1622 1301 1339 1200 1113 1134 1080 1051 1063 1062 1077 997 1010 1040 981 1006 959 993 989 965 954 968 987 931 962 929 966 1008 995 927 925 1012 974 976 1007 958 927 965 969 981 972 1047 1094 1222 1397 1479 1424 1258 1153 1134 1115 1191 1248 1202 1139 1076 1024 1001 988 964 930 972 1030 990 968 959 936 967 981 968 972 982 1004 1011 1013 1040 1042 1068 1080 1103 1148 1318 1569 1904 2045 1833 1401 1316 1222 1350 1431 1494 1414 1156 1107 1076 1094 950 975 960 995 987 959 932 926 944 933 978 987 955 948 1021 976 952 937 992 972 916 918 985 919 905 938 937 962 934 953 961 1005 963 988 1022 939 999 1035 974 984 1061 1051 1039 1073 1044 1067 1112 1195 1351 1513 1921 2469 2636 2234 1706 1467 1466 1525 1721 1950 1837 1580 1405 1244 1171 1209 1260 1269 1344 1425 1486 1597 1692 1809 1892 2039 2347 2885 3776 5420 8268 12619 16504 16420 12023 7816 5716 5543 6670 8537 9555 8196 5522 3592 2665 2142 1858 1692 1692 1522 1495 1521 1463 1417 1403 1524 1619 1754 2101 2479 3459 5200 7948 9900 8459 5413 3557 3045 3274 4059 5123 5334 4254 2877 2021 1635 1443 1292 1195 1133 1125 1127 1084 1041 978 1050 1004 1010 1011 988 966 895 904 919 954 913 880 887 861 855 873 869 889 898 888 890 891 868 837 833 810 784 785 808 817 807 825 837 825 818 825 815 789 790 809 816 783 766 802 812 819 818 796 770 771 804 819 787 787 821 851 829 831 789 825 805 804 802 791 845 858 846 858 846 813 873 874 857 869 923 1013 1152 1387 1647 1757 1516 1292 1007 982 1029 1059 1207 1265 1117 1016 915 841 838 892 913 843 848 831 825 877 875 826 821 837 843 849 808 780 803 809 832 839 836 803 827 825 797 780 780 762 786 807 803 793 807 778 722 735 784 793 771 761 779 785 760 761 794 802 780 795 784 783 777 822 822 770 748 774 759 818 833 804 842 896 926 976 940 886 868 839 857 804 822 863 837 778 763 810 768 776 767 782 742 749 789 833 776 804 800 820 805 877 858 752 810 840 811 805 813 807 817 830 816 738 774 760 773 791 768 791 777 790 804 766 782 768 740 740 747 743 768 761 731 770 804 789 765 773 789 787 774 786 774 767 778 816 866 829 821 889 914 948 986 1054 1302 1697 2216 2632 2442 1856 1413 1198 1185 1249 1453 1688 1760 1640 1414 1339 1344 1321 1146 998 937 887 954 1013 1043 1097 1051 967 994 1028 1050 994 914 885 860 861 835 794 850 967 805 757 720 717 769 736 728 756 716 793 739 723 749 685 708 697 768 687 713 719 716 711 736 731 772 743 748 714 686 709 726 677 698 672 729 690 661 701 708 666 661 703 748 726 690 686 718 734 723 740 738 718 697 685 702 723 716 715 717 708 715 722 708 714 746 750 748 715 713 725 724 698 696 710 712 712 729 730 718 751 776 782 771 767 828 820 941 1054 1266 1537 1609 1419 1164 954 894 931 886 1017 1125 1150 1020 972 882 822 753 721 750 701 719 749 719 773 775 775 732 771 739 732 720 724 773 806 824 898 828 804 751 745 767 756 747 789 797 768 744 727 757 729 696 706 712 699 701 705 677 683 704 676 690 694 659 692 724 735 734 701 691 699 715 733 749 748 733 737 729 718 718 749 770 766 765 763 781 790 770 827 892 899 958 973 1019 1175 1392 1807 2567 3480 4082 3684 2728 1919 1519 1312 1403 1598 2018 2369 2469 2130 1638 1247 1065 944 907 874 796 824 790 776 793 765 757 693 708 739 703 722 732 808 716 763 761 686 717 714 719 731 712 749 743 741 767 776 713 717 747 733 726 720 731 729 736 768 753 764 779 743 743 783 815 801 818 853 885 938 994 1082 1299 1657 2138 2617 2740 2363 1824 1488 1342 1256 1257 1359 1556 1764 1768 1568 1337 1141 968 882 856 794 789 783 775 733 735 754 699 701 697 683 696 644 693 684 740 690 669 708 692 679 658 678 682 691 724 630 637 672 669 667 718 700 652 670 745 684 658 663 652 649 701 643 633 645 676 689 657 662 658 639 661 665 671 698 672 671 704 680 690 705 679 726 778 766 722 697 728 736 764 775 742 721 731 764 740 699 680 708 740 729 691 691 727 700 703 736 694 658 685 692 659 673 696 714 691 678 678 681 733 773 800 795 841 959 1111 1329 1385 1250 1044 937 844 851 850 863 910 962 996 982 935 832 785 758 748 681 722 685 703 668 713 675 655 713 650 664 708 651 656 651 694 687 667 660 612 696 629 696 667 697 682 681 651 644 660 679 694 689 695 705 710 729 729 765 853 844 872 927 871 857 868 847 856 838 856 891 934 1019 1051 1055 1111 1214 1419 1704 2260 3245 4604 5878 5842 4507 3177 2294 1794 1605 1653 1853 2266 2909 3408 3257 2600 1922 1471 1222</intensities>
			</dataPoints>
			<nonAmbientPoints type="Temperature" unit="K">
				<measurementTimes unit="seconds" deltaTime="1">0</measurementTimes>
				<nonAmbientValues>298.000</nonAmbientValues>
			</nonAmbientPoints>
		</scan>
	</xrdMeasurement>
</xrdMeasurements>