File: Mixtures/xrdml/NIST Rutile (10%) with NIST Corundum (90%).XRDML
<?xml version="1.0" encoding="UTF-8"?>
<xrdMeasurements xmlns="http://www.xrdml.com/XRDMeasurement/1.3" xmlns:xsi="http://www.w3.org/2001/XMLSchema-instance" xsi:schemaLocation="http://www.xrdml.com/XRDMeasurement/1.3 http://www.xrdml.com/XRDMeasurement/1.3/XRDMeasurement.xsd" status="Completed">
	<comment>
		<entry>Configuration=Spinner Stage, Owner=User-1, Creation date=12/11/2006 3:54:51 PM</entry>
		<entry>Goniometer=PW3050/60 (Theta/Theta); Minimum step size 2Theta:0.001; Minimum step size Omega:0.001</entry>
		<entry>Sample stage=Spinner PW3064</entry>
		<entry>Diffractometer system=XPERT-PRO</entry>
		<entry>Measurement program=Rutile with ISTD, Owner=User-1, Creation date=1/19/2010 2:58:36 PM</entry>
		<entry>Rutile (NIST 674) &amp; ISTD Corundum (NIST 676a)</entry>
	</comment>
	<sample type="To be analyzed">
		<id>NIST Rutile 90A with NIST ISTD</id>
		<name>Rutile 674 (old) 10.0 wt% + NIST Corundum (676a) 90.0 wt%</name>
		<preparedBy>Ashraf Z Khan</preparedBy>
	</sample>
	<xrdMeasurement measurementType="Scan" status="Completed">
		<usedWavelength intended="K-Alpha 1">
			<kAlpha1 unit="Angstrom">1.540598</kAlpha1>
			<kAlpha2 unit="Angstrom">1.544426</kAlpha2>
			<kBeta unit="Angstrom">1.392250</kBeta>
			<ratioKAlpha2KAlpha1>0.500000</ratioKAlpha2KAlpha1>
		</usedWavelength>
		<incidentBeamPath>
			<radius unit="mm">240.000</radius>
			<xRayTube>
				<tension unit="kV">45</tension>
				<current unit="mA">40</current>
				<anodeMaterial>Cu</anodeMaterial>
			</xRayTube>
			<divergenceSlit xsi:type="fixedDivergenceSlitType">
				<angle unit="deg">0.250</angle>
			</divergenceSlit>
		</incidentBeamPath>
		<diffractedBeamPath>
			<radius unit="mm">240.000</radius>
			<receivingSlit>
				<height unit="mm">0.100</height>
			</receivingSlit>
		</diffractedBeamPath>
		<scan appendNumber="0" mode="Continuous" scanAxis="Gonio" status="Completed">
			<header>
				<startTimeStamp>2010-03-23T10:49:19</startTimeStamp>
				<author>
					<name>mplabs</name>
				</author>
				<source>
					<applicationSoftware version="2.2.5">X'Pert HighScore Plus</applicationSoftware>
				</source>
			</header>
			<dataPoints>
				<positions axis="2Theta" unit="deg">
					<startPosition>20.002</startPosition>
					<endPosition>89.968</endPosition>
				</positions>
				<commonCountingTime unit="seconds">657.390</commonCountingTime>
				<intensities unit="counts">8752 8747 8848 8562 8594 8645 8668 8599 8639 8526 8415 8420 8413 8563 8556 8581 8507 8538 8485 8557 8434 8488 8530 8403 8416 8527 8303 8269 8258 8361 8341 8329 8358 8260 8241 8192 8135 8262 8206 8194 8223 8148 8154 8164 8121 8151 8125 8138 8178 8127 8069 8063 8058 7997 8035 8055 8006 8059 8008 7917 7831 7865 8032 7886 7844 7864 7787 7855 7775 7756 7832 7957 7856 7859 7760 7725 7819 7639 7680 7729 7862 7835 7720 7696 7612 7663 7656 7653 7616 7595 7462 7569 7624 7578 7639 7535 7485 7413 7512 7609 7536 7555 7528 7462 7453 7411 7403 7421 7377 7322 7326 7459 7412 7386 7422 7335 7382 7464 7476 7506 7495 7327 7253 7288 7188 7323 7216 7141 7090 7191 7205 7205 7144 7074 7038 7156 7100 7116 7119 7132 7147 6992 6989 7010 6957 6933 7010 7039 7032 6953 6960 7008 6962 6944 6963 6988 6942 6860 6770 6835 6925 6860 6838 6820 6832 6792 6724 6857 6876 6861 6884 6845 6714 6787 6771 6813 6839 6727 6795 6722 6926 7081 7061 7287 7208 6937 7071 7154 6939 6894 7012 6985 7055 6990 7072 7172 6982 7007 7269 7455 7491 7768 7867 8102 8665 9266 9940 10846 12398 14203 17383 21543 28273 37367 50507 67119 70860 55518 44803 32230 19689 13547 11181 9752 8779 8253 7909 7671 7368 7158 7132 6935 6742 6524 6563 6569 6639 6646 6455 6344 6408 6306 6284 6234 6279 6304 6286 6293 6327 6268 6205 6347 6342 6305 6269 6113 6246 6346 6228 6205 6190 6158 6070 6075 6197 6244 6360 6239 6165 6148 6120 6102 6166 6341 6506 6499 6818 7004 7212 7762 8502 9490 10974 13308 16991 22035 28714 33261 31288 24909 20595 15529 10597 8349 7345 6962 6631 6466 6264 6056 6041 6058 5982 5930 5759 5746 5617 5712 5569 5713 5613 5709 5663 5564 5673 5656 5572 5604 5571 5632 5658 5539 5563 5665 5522 5440 5442 5435 5456 5370 5333 5359 5383 5356 5343 5325 5316 5401 5436 5340 5303 5293 5237 5185 5228 5277 5386 5403 5313 5351 5411 5376 5259 5111 5115 5240 5269 5167 5108 5125 5142 5175 5125 5076 5066 5081 5139 5155 5159 5075 5104 5089 5030 5098 5045 4959 4992 4924 5056 4989 5027 4867 5046 5033 5024 5086 4983 4855 4965 4920 4868 4841 4855 4873 5011 4828 5043 4921 4967 4913 4755 4799 4911 4817 4868 4880 4878 4963 4899 4792 4762 4688 4784 4702 4693 4611 4749 4744 4686 4631 4689 4669 4734 4690 4708 4580 4625 4590 4740 4654 4622 4548 4691 4720 4781 4722 4635 4577 4580 4664 4602 4589 4614 4526 4480 4532 4572 4540 4611 4747 4715 4614 4540 4540 4567 4491 4448 4454 4415 4433 4486 4458 4387 4427 4489 4393 4383 4374 4362 4356 4336 4334 4339 4288 4294 4420 4412 4386 4281 4315 4341 4419 4432 4331 4191 4309 4284 4307 4433 4370 4287 4182 4185 4240 4172 4270 4233 4193 4298 4215 4232 4314 4164 4103 4193 4255 4167 4334 4191 4158 4179 4112 4159 4083 4191 4163 4125 4144 4075 4023 4107 4104 4050 4059 4124 4138 4052 4084 4126 4044 4077 4083 4117 4215 4192 4267 4453 4548 4536 4510 4486 4436 4448 4379 4359 4317 4416 4492 4433 4385 4337 4359 4394 4423 4342 4343 4466 4503 4477 4344 4387 4589 4573 4476 4629 4840 4933 4957 5038 5279 5559 5969 6405 6910 7778 9192 10918 13198 16823 22371 31133 44157 63370 86226 97255 78948 58682 54859 45488 26663 16035 11681 9350 7955 7180 6382 5969 5647 5198 5086 4974 4860 4783 4669 4616 4497 4610 4628 4587 4594 4689 4819 4968 5213 5771 6568 7668 9802 12636 15406 15255 12336 10727 10166 8442 6445 5131 4704 4513 4271 4162 4188 4089 4128 4062 3993 4016 4063 4034 3951 3947 4006 3908 3906 3941 3924 3925 3951 3910 3922 3883 3855 3911 3855 3768 3817 3870 3908 3875 3873 3918 3853 3890 3933 4007 4005 3937 4038 4114 4186 4213 4265 4564 4726 5016 5391 5759 6521 7656 9081 11234 14703 20494 28503 37905 41986 33585 25478 24648 22597 14547 9260 7093 6139 5485 5016 4790 4568 4219 4216 4044 3977 3857 3863 3688 3775 3827 3684 3724 3731 3721 3655 3549 3462 3673 3616 3599 3576 3615 3656 3593 3544 3457 3437 3407 3478 3523 3531 3667 3606 3663 3752 3817 3782 3713 3777 3953 4246 4629 4820 4643 4381 4281 4190 3971 3655 3453 3353 3433 3487 3360 3292 3286 3286 3279 3254 3290 3327 3299 3266 3288 3281 3212 3247 3286 3217 3178 3191 3195 3234 3286 3287 3306 3269 3318 3256 3146 3173 3200 3211 3107 3120 3181 3153 3228 3190 3215 3133 3102 3136 3161 3089 3122 3174 3115 3181 3154 3229 3104 3110 3130 3237 3241 3139 3183 3195 3151 3282 3151 3315 3408 3523 3654 3951 4417 5156 6320 7648 8527 7445 6352 6116 5897 5229 4256 3649 3458 3354 3306 3245 3316 3261 3376 3586 3783 3900 3826 3548 3654 3718 3600 3430 3474 3444 3262 3214 3235 3186 3151 3184 3201 3186 3238 3222 3226 3297 3232 3162 3148 3150 3247 3325 3286 3202 3191 3267 3364 3389 3289 3314 3465 3472 3381 3403 3409 3481 3559 3583 3692 3812 3943 3981 4138 4282 4457 4796 5148 5817 6544 7387 8372 9861 11692 14558 19187 26423 38283 55596 79290 99969 90458 60914 51704 55177 52004 33118 18752 12653 9831 8105 6948 6288 5700 5175 4751 4419 4179 4089 3974 3942 3991 3904 4072 4341 4584 5056 5074 4679 4272 4156 4115 3989 3542 3276 3168 3080 3119 3184 3086 2983 3026 3000 2947 2918 2839 2917 2914 2871 2888 2898 2878 2803 2821 2821 2763 2796 2818 2751 2736 2769 2798 2724 2655 2741 2772 2711 2667 2708 2733 2787 2711 2656 2717 2776 2757 2746 2747 2689 2690 2688 2657 2690 2655 2634 2632 2688 2749 2722 2704 2695 2620 2688 2722 2642 2628 2684 2617 2646 2614 2734 2783 2753 2854 2840 2870 3134 3252 3581 3828 3462 3164 3189 3166 3143 2913 2768 2685 2715 2550 2554 2542 2554 2527 2557 2475 2470 2534 2614 2497 2478 2615 2601 2480 2518 2577 2484 2502 2539 2554 2550 2542 2522 2580 2681 2668 2698 2730 2620 2526 2476 2474 2464 2452 2470 2563 2569 2523 2471 2500 2552 2497 2480 2463 2419 2363 2382 2444 2420 2382 2332 2392 2427 2396 2402 2363 2433 2502 2474 2508 2484 2454 2462 2413 2377 2396 2478 2338 2366 2419 2347 2303 2341 2359 2334 2411 2302 2324 2365 2370 2356 2303 2293 2349 2334 2318 2352 2352 2313 2314 2376 2327 2306 2359 2237 2299 2279 2303 2267 2279 2304 2275 2269 2211 2114 2288 2336 2350 2277 2305 2290 2257 2225 2210 2198 2254 2309 2319 2310 2347 2355 2263 2221 2225 2249 2230 2219 2196 2210 2266 2247 2250 2265 2268 2277 2327 2255 2208 2218 2192 2243 2285 2302 2323 2269 2205 2208 2238 2234 2211 2199 2182 2227 2293 2278 2265 2231 2211 2304 2323 2325 2395 2391 2317 2323 2398 2324 2410 2362 2309 2333 2318 2255 2239 2232 2376 2349 2440 2336 2362 2322 2271 2312 2331 2268 2343 2325 2515 2369 2302 2348 2464 2439 2547 2584 2591 2471 2414 2430 2429 2309 2365 2409 2428 2570 2452 2487 2442 2462 2479 2531 2572 2540 2640 2582 2724 2869 2876 2959 3136 3347 3513 3747 4217 4648 5133 5850 6741 8096 10482 14527 20391 28852 38386 41919 34208 24335 20971 22213 23639 20595 14040 9067 6514 5227 4611 4099 3638 3373 3289 3187 3043 2932 2804 2645 2673 2642 2477 2461 2536 2460 2468 2438 2386 2393 2398 2377 2364 2325 2305 2309 2296 2271 2315 2208 2264 2198 2274 2246 2236 2291 2320 2286 2357 2394 2416 2420 2370 2375 2572 2548 2599 2737 2898 3098 3351 3737 4626 5817 7993 10791 14365 15718 12860 9213 7945 8332 9267 8645 6536 4643 3557 3034 2804 2603 2517 2543 2457 2407 2258 2231 2286 2291 2217 2149 2227 2183 2149 2174 2191 2200 2188 2236 2225 2188 2146 2095 2129 2139 2167 2234 2264 2291 2276 2254 2280 2324 2374 2356 2332 2355 2294 2284 2318 2275 2222 2237 2269 2274 2270 2303 2275 2274 2273 2217 2267 2277 2303 2335 2342 2334 2241 2269 2257 2329 2404 2430 2373 2394 2406 2473 2502 2583 2549 2668 2912 3093 3777 4304 5295 6354 6208 5205 4201 4028 4261 4696 4450 3832 3321 3174 3109 3020 3024 3052 3196 3426 3583 3700 3927 4202 4743 5369 6069 6778 7576 8729 10232 12884 17118 23584 33781 48438 67211 80609 70350 48575 36564 35549 40526 44009 37633 24973 15466 10691 8277 6802 5841 5154 4612 4107 3708 3567 3419 3226 3050 2911 2843 2795 2736 2627 2578 2551 2490 2420 2442 2423 2351 2332 2352 2357 2292 2255 2194 2168 2147 2136 2132 2078 2094 2060 2151 2186 2131 2088 2056 2060 2063 2071 2075 2105 2032 2056 2043 2051 2040 2170 2117 2039 2026 2061 2053 2043 2054 2077 2088 2143 2096 2182 2255 2105 2110 2112 2135 2325 2352 2466 2779 3070 3621 4024 3729 3034 2831 2788 2878 3020 2947 2584 2291 2193 2127 2031 2031 1936 1974 2005 1982 1958 1930 1977 1978 1947 1946 1965 2008 1964 1929 1968 1948 1909 1934 1978 2018 2023 1929 1956 2053 2023 2008 2040 2114 2135 2178 2205 2214 2300 2421 2498 2654 2970 3443 4104 4690 4983 4708 4521 4953 6059 7627 8970 8704 6552 4807 4443 4604 4971 5046 4504 3408 2776 2490 2355 2249 2133 2035 2017 1915 1995 1934 1985 1935 1916 1913 1863 1857 1929 1951 1851 1860 1808 1911 1834 1759 1825 1854 1851 1891 1911 1910 1843 1865 1878 1841 1866 1877 1917 1922 1939 1973 1992 2042 2261 2474 2798 3298 3697 3539 3022 2554 2460 2527 2666 2687 2580 2263 1984 1894 1823 1872 1914 1827 1797 1824 1799 1766 1807 1832 1809 1798 1758 1714 1721 1759 1757 1744 1714 1767 1769 1666 1701 1798 1764 1724 1753 1785 1796 1870 1877 1883 1896 2060 2356 2549 2902 3347 3640 3266 2717 2438 2454 2477 2662 2731 2494 2168 2079 1806 1910 1826 1827 1823 1837 1844 1870 1778 1786 1786 1828 1789 1740 1753 1758 1785 1743 1712 1724 1716 1763 1739 1779 1736 1805 1748 1765 1788 1757 1752 1782 1794 1784 1826 1851 1786 1781 1750 1738 1771 1789 1842 1886 1887 1968 2017 2013 1963 1993 2005 2002 2039 2099 2094 2036 2005 2028 2018 1975 1992 2011 2093 2209 2246 2269 2260 2307 2486 2614 2711 2926 3167 3338 3564 3959 4446 5194 6352 8160 10863 14880 20931 27274 30093 24927 16722 12620 11785 13326 15632 17217 14675 9746 6528 4976 4331 3763 3265 3014 2912 2675 2569 2416 2309 2290 2346 2253 2194 2144 2203 2134 2138 2119 2108 2072 2124 2241 2187 2057 2112 2261 2183 2130 2261 2320 2346 2322 2361 2415 2608 2776 2930 2977 3080 3398 3591 3823 4156 4623 5038 5720 6908 8639 11169 15525 22016 30856 40771 44528 36142 24218 17501 16227 18041 21619 24277 21995 15711 10158 7046 5461 4623 4100 3754 3412 3179 3060 2905 2709 2691 2701 2729 2779 2904 3157 3616 4410 5366 6069 5927 4905 3790 3290 3261 3480 3850 4094 3793 3074 2555 2292 2092 2031 1957 1976 1915 1914 1902 1892 1908 2004 1850 1839 1975 2091 2284 2497 3020 3672 3941 3516 2962 2543 2326 2318 2550 2765 2737 2531 2170 1978 1905 1785 1742 1763 1754 1749 1793 1864 1990 2059 2255 2457 2432 2286 2048 1917 1906 1890 1926 2019 2005 1886 1786 1662 1615 1621 1587 1620 1565 1584 1571 1553 1562 1619 1621 1576 1581 1579 1530 1477 1494 1536 1570 1543 1489 1492 1503 1500 1512 1593 1576 1546 1570 1494 1497 1577 1517 1536 1559 1490 1477 1501 1514 1517 1511 1548 1540 1444 1463 1474 1558 1520 1499 1472 1512 1471 1459 1475 1478 1491 1486 1529 1505 1565 1552 1583 1570 1632 1621 1743 1749 1590 1547 1532 1524 1565 1624 1585 1525 1523 1451 1441 1440 1511 1544 1474 1493 1443 1512 1444 1416 1453 1435 1478 1498 1519 1479 1463 1480 1477 1455 1469 1416 1380 1450 1451 1416 1434 1480 1471 1471 1475 1440 1429 1426 1467 1467 1409 1403 1413 1437 1479 1498 1490 1491 1509 1492 1464 1510 1538 1500 1555 1606 1601 1634 1654 1652 1741 1948 2161 2482 2628 2472 2129 1946 1885 1824 1879 1981 2052 1992 1805 1663 1624 1642 1597 1551 1513 1486 1507 1469 1497 1480 1478 1443 1535 1476 1528 1470 1560 1482 1558 1499 1508 1392 1397 1488 1539 1488 1457 1492 1457 1413 1523 1470 1484 1492 1487 1427 1398 1464 1459 1497 1497 1464 1455 1466 1510 1511 1464 1462 1441 1454 1501 1478 1474 1453 1482 1508 1496 1506 1506 1514 1510 1530 1568 1520 1564 1662 1663 1674 1719 1760 1854 2003 2135 2331 2514 2507 2472 2489 2615 2854 3132 3680 4289 5381 7008 9169 11796 13551 12490 9089 6594 5554 5547 6048 7005 8211 8990 8458 7438 7330 8179 8720 7702 5688 4407 3692 3548 3656 4219 4818 4823 4182 3219 2555 2203 2031 1977 1757 1751 1682 1598 1657 1637 1520 1538 1495 1509 1445 1526 1510 1461 1461 1495 1431 1485 1506 1438 1438 1408 1399 1355 1377 1426 1419 1461 1429 1440 1388 1339 1319 1354 1368 1395 1377 1384 1348 1369 1386 1338 1354 1372 1346 1313 1302 1306 1340 1346 1353 1359 1364 1398 1358 1337 1334 1325 1369 1381 1370 1355 1373 1332 1332 1352 1344 1300 1351 1335 1330 1340 1312 1336 1345 1421 1375 1376 1420 1461 1468 1514 1579 1531 1582 1463 1401 1499 1420 1398 1471 1456 1461 1501 1554 1530 1509 1539 1492 1549 1541 1512 1631 1639 1677 1881 1963 1989 1943 1941 2019 2247 2493 2858 3518 4295 5494 6088 5315 4024 3117 2779 2626 2688 2938 3249 3592 3406 2863 2297 2014 1828 1717 1600 1600 1497 1471 1461 1456 1406 1362 1413 1383 1369 1415 1409 1360 1310 1321 1338 1338 1319 1307 1339 1332 1329 1324 1314 1336 1320 1342 1335 1299 1315 1327 1330 1316 1338 1322 1359 1316 1384 1391 1361 1414 1445 1558 1652 1861 2081 2171 2045 1852 1634 1551 1497 1529 1516 1620 1717 1726 1674 1533 1428 1376 1415 1379 1333 1435 1342 1302 1269 1286 1337 1316 1396 1405 1307 1412 1391 1531 1518 1644 1842 1852 1737 1658 1459 1450 1381 1455 1447 1568 1558 1576 1547 1444 1381 1369 1301 1337 1380 1371 1409 1394 1359 1314 1359 1406 1405 1392 1402 1415 1437 1400 1468 1535 1590 1650 1760 1892 2034 2295 2599 3010 3445 3946 4572 4623 3888 3104 2654 2408 2378 2457 2545 2791 2952 2990 2559 2123 1828 1660 1571 1509 1441 1427 1421 1445 1365 1361 1369 1342 1377 1359 1388 1475 1481 1507 1470 1451 1378 1356 1322 1367 1346 1442 1407 1329 1436 1416 1280 1310 1360 1338 1288 1338 1289 1289 1302 1265 1319 1345 1300 1319 1294 1341 1325 1403 1375 1400 1430 1419 1415 1449 1540 1546 1663 1737 1932 2155 2464 2886 3514 4058 4089 3605 3228 3222 3399 3605 3554 3355 3204 3149 3027 2788 2455 2267 2293 2405 2346 2113 1868 1660 1571 1487 1403 1372 1412 1424 1325 1335 1328 1317 1351 1306 1271 1325 1339 1319 1328 1307 1311 1353 1401 1334 1461 1419 1421 1410 1377 1327 1325 1306 1251 1330 1356 1350 1354 1310 1347 1367 1314 1325 1279 1221 1245 1317 1330 1282 1249 1244 1241 1303 1329 1364 1261 1284 1265 1341 1367 1353 1336 1379 1397 1350 1455 1417 1414 1450 1428 1458 1537 1491 1547 1714 1742 1830 2000 2138 2422 2840 3426 4301 5389 6180 5796 4698 3612 3008 2701 2570 2658 2919 3213 3640 3891 3580 2996 2508 2222 2126 2101 2165 2375 2616 2823 2737 2370 2050 1792 1670 1611 1638 1748 1832 1887 1992 1962 1830 1651 1556 1486</intensities>
			</dataPoints>
			<nonAmbientPoints type="Temperature" unit="K">
				<measurementTimes unit="seconds" deltaTime="1">0</measurementTimes>
				<nonAmbientValues>298.000</nonAmbientValues>
			</nonAmbientPoints>
		</scan>
	</xrdMeasurement>
</xrdMeasurements>